# 异常

## 错误类型

- Error：所有错误的父类型

- ReferenceError：引用错误
a(); // Uncaught ReferenceError(没有声明a，a是undefined，无法调用)

- TypeError：数据类型错误
123(); // Uncaught TypeError(123为数字类型，无法调用)

- RangeError：数据值不在其所允许的范围内
[].length = -1; // Uncaught RangeError(length 的值不能为负数)

- SyntaxError：语法错误
var 1; // Uncaught SyntaxError

- 自定义错误
throw '错啦' // Uncaught 错啦

## 错误处理

try：使您能够测试代码块中的错误
catch：允许您处理错误
throw：允许您创建自定义错误
finally：使您能够执行代码，在 try 和 catch 之后，无论结果如何

- 捕捉错误：try...catch
    try {
        let d
        console.log(d.xxx)
    } catch (error) {
        console.log(error.message)
        console.log(error.stack)
    }

- 抛出错误：throw error
    function something() {
        if (Date.now() % 2 === 1) {
            console.log('当前时间为奇数，可以执行任务')
        } else { // 如果时间是偶数抛出异常，由调用者来处理
            throw new Error('当前时间为偶数，无法执行任务')
        }
    }

    // 调用的时候要捕获处理异常
    try {
        something()
    } catch (error) {
        alert(error.message)
    }

## finally 关键字

finally：使您能够执行代码，在 try 和 catch 之后，无论结果如何
当 finally 块中有 return 关键字时，会拦截之前所 return 的内容

```javascript
function test() {
    try {
        throw Error();
        return 'try';
    } catch (error) {
        return 'error';
    } finally {
        return 'finally';
    }
}
test(); // finally
```

## 错误对象属性

- name：错误名
- message：错误信息
- stack：函数调用栈记录信息
