# 什么是 promise

抽象表达：是 ES6 推出的进行 js 异步编程的新的解决方案
具体表达：
从语法上来说：Promise 是一个构造函数
从功能上来说：promise 对象用来封装一个异步操作并可以获取其结果

## promise 状态变化

- pending 变为 resolved
- pending 变为 rejected

只有这两种状态变化，且一个 promise 对象状态只能改变一次
无论是成功还是失败都会有一个结果数据，成功数据一般叫 value，失败数据一般叫 reason

## promise 流程

new Promise（）   此时是 pending 状态
开始执行异步操作：
    若成功，则执行resolve()，此时 promise 对象变为 resolved 状态，通过 .then 调用回调函数 onResolved()
    若失败，则执行reject()，此时 promise 对象变为 rejected 状态，回调 onRejected()

## 为什么要用promise

1. 指定回调函数的方式更加灵活
旧的：必须要在启动异步任务之前指定回调函数
promise：启动异步任务 => 返回 promise 对象 => 给 promise 对象绑定回调函数

2. 支持链式调用，可以解决回调地狱的问题
什么是回调地狱？ 回调函数嵌套使用，外部回调函数异步执行的结果是嵌套的回调函数执行的条件
回调地狱的缺点？ 不便于阅读/不便于异常处理
解决方案？ promise链式调用
终极解决方案？ async/await

回调地狱：

doSomething(function(result) {
    doSomethingElse(result, function(newResult) {
        doThirdThing(newResult, function(finalResult) {
            console.log(finalResult)
        }, failureCallback)
    }, failureCallback)
}, failureCallback)

promise链式调用解决回调地狱问题：

doSomething().then(function(result) {
    return doSomethingElse(result)
})
.then(function(newResult) {
    return doThirdThing(newResult)
})
.then(function(finalResult) {
    console.log(finalResult)
})
.catch(failureCallback)

async/await：回调地狱的终极解决方案

async function request() {
    try {
        const result = await doSomeThing()
        const newResult = await doSomethingElse(result)
        const finalResult = await doThirdThing(newResult)
        console.log(finalResult)
    }catch (error) {
        failureCallback(error)
    }
}

## Promise 原理

调用 then 方法，将想要在 Promise 异步操作成功时执行的回调放入任务队列，也就是注册回调函数
创建 Promise 实例时传入的函数会被赋予一个函数类型的参数，即 resolve，它接收一个参数 value，代表异步操作返回的结果
当一步操作执行成功后，用户会调用 resolve 方法，这时候其实真正执行的操作是将任务队列中的回调一一执行

## Promise 缺点

1. 无法取消 Promise
2. 错误需要通过回调函数来捕获。如果不设置回调函数，Promise 内部抛出的错误不会反应到外部
