# API

- Promise.all(iterable)   iterable为一个可迭代对象，如数组
这个方法返回一个新的 promise 对象，该 promise 对象在 iterable 参数对象里所有的 promise 对象都为成功状态才会触发成功回调；
一旦有任何一个 iterable 里面的 promise 对象为失败状态则触发该 promise 对象的失败回调。
这个新的 promise 对象在触发成功状态以后，会把一个包含 iterable 里所有 promise 返回值的数组作为成功回调的返回值，顺序跟iterable的顺序保持一致；
**每一个 Promise 对象是对数组的索引进行保存的，并不是 push 进去的，这样才能保证顺序**
如果这个新的 promise 对象触发了失败状态，它会把 iterable 里第一个触发失败的 promise 对象的错误信息作为它的失败错误信息。

如果可迭代对象中某个 Promise 对象中有失败回调,而又想进入 Promise.all 的成功回调的话,就要为每个 Promise 关联一个错误处理函数(catch)

```javascript
const p1 = Promise.resolve(1)
const p2 = Promise.resolve(Promise.resolve(2))
const p3 = Promise.resolve(Promise.reject(3))
Promise.all([p1, p2, p3])
.then(values => console.log(values)) // p3失败,无法进入该成功回调
.catch(err => console.log(err))

p3 = Promise.resolve(Promise.reject(3)).catch(err => err) // 为失败的 Promise 对象关联一个错误函数
Promise.all([p1, p2, p3])
.then(values => console.log(values)) // [1, 2, 3]
.catch(err => console.log(err))

// 也可以为所有 Promise 对象关联错误函数
Promise.all([p1, p2, p3].map(p => p.catch(e => e)))
```

如果可迭代对象中有非 promise 对象，则这些值会被忽视，仍会将它们放入返回数组中

```javascript
var p2 = Promise.all([1,2,3, Promise.resolve(444)]).then(val => val); // [1, 2, 3, 444]
var p3 = Promise.all([1,2,3, Promise.reject(555)]); // Promise { <state>: "rejected", <reason>: 555 }
```

- Promise.allSettled(iterable)
该方法的参数跟 Promise.all 一样
跟 Promise.all 不同的是，无论这个数组里面的 Promise 为成功还是失败状态，都会执行成功回调
返回值是一个数组，这个数组里存放的是每个 Promise 的状态和返回值

- Promise.race(iterable)
当 iterable 参数里的任意一个 promise 成功或失败后，父 promise 马上也会用子 promise 的成功返回值或失败返回值作为参数调用父 promise 绑定的相应句柄，并返回该 promise 对象。
