<!DOCTYPE html>
<html lang="en">
<head>
    <meta charset="UTF-8">
    <meta name="viewport" content="width=device-width, initial-scale=1.0">
    <meta http-equiv="X-UA-Compatible" content="ie=edge">
    <title>Document</title>
</head>
<body>
    <script>
        async function fn1() {
            // return 1;
            return Promise.resolve(2);
        }
        const result = fn1();
        console.log(result); // async 返回一个promise对象
        result.then(
            value => {
                console.log('onResolved', value); // onResolved 2
            },
            reason => {
                console.log('onRejected', reason);
            }
        )


        function fn2() {
            return new Promise((resolve, reject) => {
                setTimeout(() => {
                    resolve(3);
                }, 1000);
            })
        }
        function fn3() {
            return new Promise((resolve, reject) => {
                setTimeout(() => {
                    reject(4);
                }, 1000);
            })
        }
        async function fn4() {
            return 6;
        }
        async function fn() {
            const value1 = await fn2(); // await 右侧表达式为 resolved 状态的 promise 对象，得到的结果就是 promise 成功的 value
            const value2 = await fn4();  // await 右侧表达式不为 promise 对象，得到的结果就是表达式本身的值
            console.log(value1, value2); // 3 6
            
            try {
                const value = await fn3(); // await 右侧表达式为 rejected 状态的 promise 对象，则会报错, 要得到结果需要 try catch
            } catch (error) {
                console.log('得到失败的结果:' + error);
            }
        }
        fn();
    </script>
</body>
</html>